Workbook

Sheet Romaneios
A1: Dt. Romaneio | B1: Filial | C1: Nome Fantasia | D1: Num.PV | E1: Num.NF
A2: 46302 | B2: 101 | C2: ALBERT EINSTEIN | D2: 68513 | E2: 178745
A3: 46302 | B3: 101 | C3: ALBERT EINSTEIN | D3: 68739 | E3: 178811
A4: 46302 | B4: 101 | C4: ALBERT EINSTEIN | D4: 68741 | E4: 178810
A5: 46302 | B5: 101 | C5: ALBERT EINSTEIN | D5: 68742 | E5: 178807
A6: 46302 | B6: 101 | C6: ALBERT EINSTEIN | D6: 68753 | E6: 178812
A7: 46302 | B7: 101 | C7: ALBERT EINSTEIN | D7: 69034 | E7: 178808
A8: 46302 | B8: 101 | C8: ALBERT EINSTEIN | D8: 69493 | E8: 178809
A9: 46302 | B9: 101 | C9: DAVITA INDIANOPOLIS | D9: 67045 | E9: 178789
A10: 46302 | B10: 101 | C10: DAVITA INDIANOPOLIS | D10: 67046 | E10: 178788
A11: 46302 | B11: 101 | C11: DAVITA INDIANOPOLIS | D11: 67070 | E11: 178784
A12: 46302 | B12: 101 | C12: DAVITA INDIANOPOLIS | D12: 67071 | E12: 178787
A13: 46302 | B13: 101 | C13: ALBERT EINSTEIN | D13: 64092 | E13: 174996
... A21: 46302 | B21: 101 | C21: DASA RECIFE 61.486.6 | D21: 69745 | E21: 178815
A22: 46302 | B22: 101 | C22: BENEFICENCIA SP | E22: 178829
A23: 46302 | B23: 101 | C23: TJ RAJ 01 MATRIZ | D23: 68720 | E23: 178665
A24: 46302 | B24: 101 | C24: TJ RAJ 01 MATRIZ | D24: 69132 | E24: 178799
A25: 46302 | B25: 101 | C25: TJ RAJ 04 | D25: 67880 | E25: 176561
A26: 46302 | B26: 101 | C26: TJ RAJ 06 | D26: 67953 | E26: 178231
A27: 46302 | B27: 101 | C27: TJ RAJ 10 | D27: 67452 | E27: 178408
A28: 46302 | B28: 101 | C28: INFANTE DOM HENRIQUE | D28: 69265 | E28: 178553
A29: 46302 | B29: 101 | C29: HOSPITAL EST SUMARE | D29: 69188 | E29: 178574
A30: 46302 | B30: 101 | C30: TJ RAJ 01 MATRIZ | D30: 69126 | E30: 178691
A31: 46302 | B31: 101 | C31: TJ RAJ 04 | D31: 67736 | E31: 178655
A32: 46302 | B32: 101 | C32: TJ RAJ 04 | D32: 68714 | E32: 178664
A33: 46302 | B33: 101 | C33: TJ RAJ 04 | D33: 69107 | E33: 178673
A34: 46302 | B34: 101 | C34: TJ RAJ 04 | D34: 69113 | E34: 178674
... A36: 46302 | B36: 101 | C36: TJ RAJ 06 | D36: 69119 | E36: 178676
A37: 46303 | B37: 101 | C37: DASA PQ DUQUE CAXIAS | E37: 178864
A38: 46303 | B38: 0 | C38: DASA PQ DUQUE CAXIAS | D38: 68875 | E38: 178833
A39: 46303 | B39: 101 | C39: DASA PQ DUQUE CAXIAS | D39: 69385 | E39: 178832
A40: 46303 | B40: 101 | C40: DASA PQ DUQUE CAXIAS | D40: 69386 | E40: 178843
A41: 46303 | B41: 101 | C41: DASA PQ DUQUE CAXIAS | D41: 69552 | E41: 178842
A42: 46303 | B42: 101 | C42: DASA PQ DUQUE CAXIAS | D42: 69699 | E42: 178858
A43: 46303 | B43: 101 | C43: DASA ALTA EXCELENCIA | D43: 68655 | E43: 178845
A44: 46303 | B44: 101 | C44: DASA ALTA EXCELENCIA | D44: 69219 | E44: 178846
A45: 46303 | B45: 101 | C45: DASA DIAGNOSTICO | D45: 69475 | E45: 178854
A46: 46303 | B46: 101 | C46: DASA DIAGNOSTICO | D46: 68521 | E46: 178853
A47: 46303 | B47: 101 | C47: DASA DIAGNOSTICO | D47: 69274 | E47: 178830
A48: 46303 | B48: 101 | C48: MASTER HIGIMED RJ | D48: 69935 | E48: 178986
...

Sheet DadosRomaneios
A1: {=_xlfn.UNIQUE(Romaneios!A1:A1429)} -> Dt. Romaneio | B1: Qtd. Expedição
A2: 46302 | B2: =COUNTIF(Romaneios!A:A,DadosRomaneios!A2) -> 35
A3: 46303 | B3: =COUNTIF(Romaneios!A:A,DadosRomaneios!A3) -> 62
A4: 46304 | B4: =COUNTIF(Romaneios!A:A,DadosRomaneios!A4) -> 114
A5: 46305 | B5: =COUNTIF(Romaneios!A:A,DadosRomaneios!A5) -> 13
A6: 46306 | B6: =COUNTIF(Romaneios!A:A,DadosRomaneios!A6) -> 50
A7: 46307 | B7: =COUNTIF(Romaneios!A:A,DadosRomaneios!A7) -> 8
A8: 46308 | B8: =COUNTIF(Romaneios!A:A,DadosRomaneios!A8) -> 148
A9: 46309 | B9: =COUNTIF(Romaneios!A:A,DadosRomaneios!A9) -> 139
A10: 46310 | B10: =COUNTIF(Romaneios!A:A,DadosRomaneios!A10) -> 92
A11: 46311 | B11: =COUNTIF(Romaneios!A:A,DadosRomaneios!A11) -> 57
A12: 46312 | B12: =COUNTIF(Romaneios!A:A,DadosRomaneios!A12) -> 2
A13: 46313 | B13: =COUNTIF(Romaneios!A:A,DadosRomaneios!A13) -> 1
... A21: 46322 | B21: =COUNTIF(Romaneios!A:A,DadosRomaneios!A21) -> 76
