Workbook
Name SegmentaçãodeDados_DATA: #N/A

Sheet SEPARAÇÃO
A1: NF | B1: PV | C1: SEPARADOR | D1: DATA | E1: SKU'S | F1: TR ou NC | G1: STATUS PRODUÇÃO | H1: STATUS | I1: VOLUMES | J1: PALETES | K1: SEPARAÇÃO ($) | L1: CLIENTE | M1: OCORRÊNCIAS CLIENTES | N1: SETOR RESPONSÁVEL | O1: DADOS TRANSPORTE | P1: SOLICITANTE URGÊNCIAS | Q1: MOTIVOS
A2: =IFERROR(INDEX(NFS!F:F,MATCH(B2,NFS!E:E,0)),"") -> 179000 | B2: 69312 | C2: MIJOHNSON | D2: 46304 | E2: =IF(B2="","",COUNTIF(SKU!C:C,B2)) -> 38 | F2: CARRO PROPRIO | G2: FATURADO | H2: BACKLOG | I2: =IF(A2="","",IFERROR(VLOOKUP(TEXT(A2,"0"),#REF!,9,FALSE),"")) | K2: =IFERROR(INDEX(#REF!,MATCH(A2,#REF!,0)),"") | L2: =IFERROR(INDEX(SKU!E:E,MATCH(B2,SKU!C:C,0)),"") -> ACALANTO CLINICA | R2: =IF(COUNTIF(ROMANEIOS!K:K,A2)>0,J2,"")
A3: =IFERROR(INDEX(NFS!F:F,MATCH(B3,NFS!E:E,0)),"") -> 178891 | B3: 66744 | C3: WELINGTON | D3: 46303 | E3: =IF(B3="","",COUNTIF(SKU!C:C,B3)) -> 3 | F3: CARRO PROPRIO | G3: FATURADO | H3: BACKLOG | I3: =IF(A3="","",IFERROR(VLOOKUP(TEXT(A3,"0"),#REF!,9,FALSE),"")) | K3: =IFERROR(INDEX(#REF!,MATCH(A3,#REF!,0)),"") | L3: =IFERROR(INDEX(SKU!E:E,MATCH(B3,SKU!C:C,0)),"") -> ALBERT EINSTEIN | R3: =IF(COUNTIF(ROMANEIOS!K:K,A3)>0,J3,"")
A4: =IFERROR(INDEX(NFS!F:F,MATCH(B4,NFS!E:E,0)),"") -> 178846 | B4: 69219 | C4: RAONI | D4: 46302 | E4: =IF(B4="","",COUNTIF(SKU!C:C,B4)) -> 2 | F4: CARRO PROPRIO | G4: FATURADO | H4: SAUDAVEL | L4: =IFERROR(INDEX(SKU!E:E,MATCH(B4,SKU!C:C,0)),"") -> DASA ALTA EXCELENCIA | R4: =IF(COUNTIF(ROMANEIOS!K:K,A4)>0,J4,"")
A5: =IFERROR(INDEX(NFS!F:F,MATCH(B5,NFS!E:E,0)),"") -> 178927 | B5: 66745 | C5: WELINGTON | D5: 46303 | E5: =IF(B5="","",COUNTIF(SKU!C:C,B5)) -> 2 | F5: CARRO PROPRIO | G5: FATURADO | H5: BACKLOG | I5: =IF(A5="","",IFERROR(VLOOKUP(TEXT(A5,"0"),#REF!,9,FALSE),"")) | K5: =IFERROR(INDEX(#REF!,MATCH(A5,#REF!,0)),"") | L5: =IFERROR(INDEX(SKU!E:E,MATCH(B5,SKU!C:C,0)),"") -> ALBERT EINSTEIN | R5: =IF(COUNTIF(ROMANEIOS!K:K,A5)>0,J5,"")
A6: =IFERROR(INDEX(NFS!F:F,MATCH(B6,NFS!E:E,0)),"") -> 178831 | B6: 69552 | C6: RAONI | D6: 46302 | E6: =IF(B6="","",COUNTIF(SKU!C:C,B6)) -> 1 | F6: CARRO PROPRIO | G6: FATURADO | H6: SAUDAVEL | L6: =IFERROR(INDEX(SKU!E:E,MATCH(B6,SKU!C:C,0)),"") -> DASA PQ DUQUE CAXIAS | R6: =IF(COUNTIF(ROMANEIOS!K:K,A6)>0,J6,"")
A7: =IFERROR(INDEX(NFS!F:F,MATCH(B7,NFS!E:E,0)),"") -> 178956 | B7: 65062 | C7: WELINGTON | D7: 46303 | E7: =IF(B7="","",COUNTIF(SKU!C:C,B7)) -> 3 | F7: CARRO PROPRIO | G7: FATURADO | H7: BACKLOG | I7: =IF(A7="","",IFERROR(VLOOKUP(TEXT(A7,"0"),#REF!,9,FALSE),"")) | K7: =IFERROR(INDEX(#REF!,MATCH(A7,#REF!,0)),"") | L7: =IFERROR(INDEX(SKU!E:E,MATCH(B7,SKU!C:C,0)),"") -> ALBERT EINSTEIN | R7: =IF(COUNTIF(ROMANEIOS!K:K,A7)>0,J7,"")
A8: =IFERROR(INDEX(NFS!F:F,MATCH(B8,NFS!E:E,0)),"") -> 178856 | B8: 69261 | C8: CLAUDIO | D8: 46302 | E8: =IF(B8="","",COUNTIF(SKU!C:C,B8)) -> 5 | F8: CARRO PROPRIO | G8: FATURADO | H8: SAUDAVEL | L8: =IFERROR(INDEX(SKU!E:E,MATCH(B8,SKU!C:C,0)),"") -> MASTER HIGIMED RJ | R8: =IF(COUNTIF(ROMANEIOS!K:K,A8)>0,J8,"")
A9: =IFERROR(INDEX(NFS!F:F,MATCH(B9,NFS!E:E,0)),"") -> 178833 | B9: 68875 | C9: PAIVA | D9: 46302 | E9: =IF(B9="","",COUNTIF(SKU!C:C,B9)) -> 1 | F9: CARRO PROPRIO | G9: FATURADO | H9: SAUDAVEL | L9: =IFERROR(INDEX(SKU!E:E,MATCH(B9,SKU!C:C,0)),"") -> DASA PQ DUQUE CAXIAS | R9: =IF(COUNTIF(ROMANEIOS!K:K,A9)>0,J9,"")
A10: =IFERROR(INDEX(NFS!F:F,MATCH(B10,NFS!E:E,0)),"") -> 178832 | B10: 69385 | C10: PAIVA | D10: 46302 | E10: =IF(B10="","",COUNTIF(SKU!C:C,B10)) -> 6 | F10: CARRO PROPRIO | G10: FATURADO | H10: SAUDAVEL | L10: =IFERROR(INDEX(SKU!E:E,MATCH(B10,SKU!C:C,0)),"") -> DASA PQ DUQUE CAXIAS | R10: =IF(COUNTIF(ROMANEIOS!K:K,A10)>0,J10,"")
A11: =IFERROR(INDEX(NFS!F:F,MATCH(B11,NFS!E:E,0)),"") -> 178864 | B11: 68993 | C11: JOÃO PAULO | D11: 46302 | E11: =IF(B11="","",COUNTIF(SKU!C:C,B11)) -> 44 | F11: CARRO PROPRIO | G11: FATURADO | H11: SAUDAVEL | L11: =IFERROR(INDEX(SKU!E:E,MATCH(B11,SKU!C:C,0)),"") -> DASA PQ DUQUE CAXIAS | R11: =IF(COUNTIF(ROMANEIOS!K:K,A11)>0,J11,"")
A12: =IFERROR(INDEX(NFS!F:F,MATCH(B12,NFS!E:E,0)),"") -> 178854 | B12: 69475 | C12: RAPHAEL | D12: 46302 | E12: =IF(B12="","",COUNTIF(SKU!C:C,B12)) -> 11 | F12: CARRO PROPRIO | G12: FATURADO | H12: SAUDAVEL | L12: =IFERROR(INDEX(SKU!E:E,MATCH(B12,SKU!C:C,0)),"") -> DASA DIAGNOSTICO | R12: =IF(COUNTIF(ROMANEIOS!K:K,A12)>0,J12,"")
A13: =IFERROR(INDEX(NFS!F:F,MATCH(B13,NFS!E:E,0)),"") -> 178890 | B13: 66736 | C13: WELINGTON | D13: 46303 | E13: =IF(B13="","",COUNTIF(SKU!C:C,B13)) -> 1 | F13: CARRO PROPRIO | G13: FATURADO | H13: BACKLOG | I13: =IF(A13="","",IFERROR(VLOOKUP(TEXT(A13,"0"),#REF!,9,FALSE),"")) | K13: =IFERROR(INDEX(#REF!,MATCH(A13,#REF!,0)),"") | L13: =IFERROR(INDEX(SKU!E:E,MATCH(B13,SKU!C:C,0)),"") -> ALBERT EINSTEIN | R13: =IF(COUNTIF(ROMANEIOS!K:K,A13)>0,J13,"")
A14: =IFERROR(INDEX(NFS!F:F,MATCH(B14,NFS!E:E,0)),"") -> 178837 | B14: 69154 | C14: RAONI | D14: 46302 | E14: =IF(B14="","",COUNTIF(SKU!C:C,B14)) -> 1 | F14: CARRO PROPRIO | G14: FATURADO | H14: SAUDAVEL | L14: =IFERROR(INDEX(SKU!E:E,MATCH(B14,SKU!C:C,0)),"") -> ALBERT EINSTEIN | R14: =IF(COUNTIF(ROMANEIOS!K:K,A14)>0,J14,"")
A15: =IFERROR(INDEX(NFS!F:F,MATCH(B15,NFS!E:E,0)),"") -> 178834 | B15: 69365 | C15: RAONI | D15: 46302 | E15: =IF(B15="","",COUNTIF(SKU!C:C,B15)) -> 5 | F15: CARRO PROPRIO | G15: FATURADO | H15: SAUDAVEL | L15: =IFERROR(INDEX(SKU!E:E,MATCH(B15,SKU!C:C,0)),"") -> DASA S JOSE PINHAIS | R15: =IF(COUNTIF(ROMANEIOS!K:K,A15)>0,J15,"")
A16: =IFERROR(INDEX(NFS!F:F,MATCH(B16,NFS!E:E,0)),"") -> 178835 | B16: 69345 | C16: RAONI | D16: 46302 | E16: =IF(B16="","",COUNTIF(SKU!C:C,B16)) -> 9 | F16: CARRO PROPRIO | G16: FATURADO | H16: SAUDAVEL | L16: =IFERROR(INDEX(SKU!E:E,MATCH(B16,SKU!C:C,0)),"") -> DASA CASCAVEL | R16: =IF(COUNTIF(ROMANEIOS!K:K,A16)>0,J16,"")
A17: =IFERROR(INDEX(NFS!F:F,MATCH(B17,NFS!E:E,0)),"") -> 178814 | B17: 69671 | C17: MTC | D17: 46302 | E17: =IF(B17="","",COUNTIF(SKU!C:C,B17)) -> 1 | F17: CARRO PROPRIO | G17: FATURADO | H17: SAUDAVEL | L17: =IFERROR(INDEX(SKU!E:E,MATCH(B17,SKU!C:C,0)),"") -> HAPVIDA | R17: =IF(COUNTIF(ROMANEIOS!K:K,A17)>0,J17,"")
A18: =IFERROR(INDEX(NFS!F:F,MATCH(B18,NFS!E:E,0)),"") -> 178838 | B18: 69386 | C18: MAURICIO | D18: 46302 | E18: =IF(B18="","",COUNTIF(SKU!C:C,B18)) -> 4 | F18: CARRO PROPRIO | G18: FATURADO | H18: SAUDAVEL | L18: =IFERROR(INDEX(SKU!E:E,MATCH(B18,SKU!C:C,0)),"") -> DASA PQ DUQUE CAXIAS | R18: =IF(COUNTIF(ROMANEIOS!K:K,A18)>0,J18,"")
A19: =IFERROR(INDEX(NFS!F:F,MATCH(B19,NFS!E:E,0)),"") -> 178851 | B19: 69424 | C19: MAURICIO | D19: 46302 | E19: =IF(B19="","",COUNTIF(SKU!C:C,B19)) -> 5 | F19: CARRO PROPRIO | G19: FATURADO | H19: SAUDAVEL | I19: =IF(A19="","",IFERROR(VLOOKUP(TEXT(A19,"0"),#REF!,9,FALSE),"")) | K19: =IFERROR(INDEX(#REF!,MATCH(A19,#REF!,0)),"") | L19: =IFERROR(INDEX(SKU!E:E,MATCH(B19,SKU!C:C,0)),"") -> ALBERT EINSTEIN | R19: =IF(COUNTIF(ROMANEIOS!K:K,A19)>0,J19,"")
A20: =IFERROR(INDEX(NFS!F:F,MATCH(B20,NFS!E:E,0)),"") -> 178866 | B20: 69426 | C20: LEANDRO | D20: 46302 | E20: =IF(B20="","",COUNTIF(SKU!C:C,B20)) -> 6 | F20: CARRO PROPRIO | G20: FATURADO | H20: SAUDAVEL | I20: =IF(A20="","",IFERROR(VLOOKUP(TEXT(A20,"0"),#REF!,9,FALSE),"")) | K20: =IFERROR(INDEX(#REF!,MATCH(A20,#REF!,0)),"") | L20: =IFERROR(INDEX(SKU!E:E,MATCH(B20,SKU!C:C,0)),"") -> ALBERT EINSTEIN | R20: =IF(COUNTIF(ROMANEIOS!K:K,A20)>0,J20,"")
A21: =IFERROR(INDEX(NFS!F:F,MATCH(B21,NFS!E:E,0)),"") -> 178865 | B21: 69427 | C21: LEANDRO | D21: 46302 | E21: =IF(B21="","",COUNTIF(SKU!C:C,B21)) -> 5 | F21: CARRO PROPRIO | G21: FATURADO | H21: SAUDAVEL | I21: =IF(A21="","",IFERROR(VLOOKUP(TEXT(A21,"0"),#REF!,9,FALSE),"")) | K21: =IFERROR(INDEX(#REF!,MATCH(A21,#REF!,0)),"") | L21: =IFERROR(INDEX(SKU!E:E,MATCH(B21,SKU!C:C,0)),"") -> ALBERT EINSTEIN | R21: =IF(COUNTIF(ROMANEIOS!K:K,A21)>0,J21,"")
A22: =IFERROR(INDEX(NFS!F:F,MATCH(B22,NFS!E:E,0)),"") -> 178953 | B22: 68904 | C22: RAONI | D22: 46303 | E22: =IF(B22="","",COUNTIF(SKU!C:C,B22)) -> 1 | F22: CARRO PROPRIO | G22: FATURADO | H22: BACKLOG | I22: =IF(A22="","",IFERROR(VLOOKUP(TEXT(A22,"0"),#REF!,9,FALSE),"")) | K22: =IFERROR(INDEX(#REF!,MATCH(A22,#REF!,0)),"") | L22: =IFERROR(INDEX(SKU!E:E,MATCH(B22,SKU!C:C,0)),"") -> ALBERT EINSTEIN | R22: =IF(COUNTIF(ROMANEIOS!K:K,A22)>0,J22,"")
A23: =IFERROR(INDEX(NFS!F:F,MATCH(B23,NFS!E:E,0)),"") -> 178952 | B23: 68737 | C23: RAONI | D23: 46303 | E23: =IF(B23="","",COUNTIF(SKU!C:C,B23)) -> 2 | F23: CARRO PROPRIO | G23: FATURADO | H23: BACKLOG | I23: =IF(A23="","",IFERROR(VLOOKUP(TEXT(A23,"0"),#REF!,9,FALSE),"")) | K23: =IFERROR(INDEX(#REF!,MATCH(A23,#REF!,0)),"") | L23: =IFERROR(INDEX(SKU!E:E,MATCH(B23,SKU!C:C,0)),"") -> ALBERT EINSTEIN | R23: =IF(COUNTIF(ROMANEIOS!K:K,A23)>0,J23,"")
A24: =IFERROR(INDEX(NFS!F:F,MATCH(B24,NFS!E:E,0)),"") -> 178962 | B24: 68749 | C24: RAONI | D24: 46303 | E24: =IF(B24="","",COUNTIF(SKU!C:C,B24)) -> 1 | F24: CARRO PROPRIO | G24: FATURADO | H24: BACKLOG | I24: =IF(A24="","",IFERROR(VLOOKUP(TEXT(A24,"0"),#REF!,9,FALSE),"")) | K24: =IFERROR(INDEX(#REF!,MATCH(A24,#REF!,0)),"") | L24: =IFERROR(INDEX(SKU!E:E,MATCH(B24,SKU!C:C,0)),"") -> ALBERT EINSTEIN | R24: =IF(COUNTIF(ROMANEIOS!K:K,A24)>0,J24,"")
A25: =IFERROR(INDEX(NFS!F:F,MATCH(B25,NFS!E:E,0)),"") -> 178961 | B25: 68736 | C25: RAONI | D25: 46303 | E25: =IF(B25="","",COUNTIF(SKU!C:C,B25)) -> 1 | F25: CARRO PROPRIO | G25: FATURADO | H25: BACKLOG | I25: =IF(A25="","",IFERROR(VLOOKUP(TEXT(A25,"0"),#REF!,9,FALSE),"")) | K25: =IFERROR(INDEX(#REF!,MATCH(A25,#REF!,0)),"") | L25: =IFERROR(INDEX(SKU!E:E,MATCH(B25,SKU!C:C,0)),"") -> ALBERT EINSTEIN | R25: =IF(COUNTIF(ROMANEIOS!K:K,A25)>0,J25,"")
A26: =IFERROR(INDEX(NFS!F:F,MATCH(B26,NFS!E:E,0)),"") -> 178857 | B26: 69794 | C26: RAONI | D26: 46302 | E26: 1 | F26: CARRO PROPRIO | G26: FATURADO | H26: SAUDAVEL | I26: =IF(A26="","",IFERROR(VLOOKUP(TEXT(A26,"0"),#REF!,9,FALSE),"")) | K26: =IFERROR(INDEX(#REF!,MATCH(A26,#REF!,0)),"") | L26: REAL E BENEMERITA | R26: =IF(COUNTIF(ROMANEIOS!K:K,A26)>0,J26,"")
A27: =IFERROR(INDEX(NFS!F:F,MATCH(B27,NFS!E:E,0)),"") -> 179018 | B27: 69093 | C27: IVAN | D27: 46304 | E27: =IF(B27="","",COUNTIF(SKU!C:C,B27)) -> 1 | F27: CARRO PROPRIO | G27: FATURADO | H27: BACKLOG | I27: =IF(A27="","",IFERROR(VLOOKUP(TEXT(A27,"0"),#REF!,9,FALSE),"")) | K27: =IFERROR(INDEX(#REF!,MATCH(A27,#REF!,0)),"") | L27: =IFERROR(INDEX(SKU!E:E,MATCH(B27,SKU!C:C,0)),"") -> ALBERT EINSTEIN | R27: =IF(COUNTIF(ROMANEIOS!K:K,A27)>0,J27,"")
A28: =IFERROR(INDEX(NFS!F:F,MATCH(B28,NFS!E:E,0)),"") -> 178858 | B28: 69699 | C28: MATHEUS | D28: 46302 | E28: 1 | F28: CARRO PROPRIO | G28: FATURADO | H28: SAUDAVEL | I28: =IF(A28="","",IFERROR(VLOOKUP(TEXT(A28,"0"),#REF!,9,FALSE),"")) | K28: =IFERROR(INDEX(#REF!,MATCH(A28,#REF!,0)),"") | L28: DIAGNOSTICOS DA AMERICA SA | R28: =IF(COUNTIF(ROMANEIOS!K:K,A28)>0,J28,"")
A29: =IFERROR(INDEX(NFS!F:F,MATCH(B29,NFS!E:E,0)),"") -> 178998 | B29: 69352 | C29: WELINGTON | D29: 46304 | E29: =IF(B29="","",COUNTIF(SKU!C:C,B29)) -> 2 | F29: CARRO PROPRIO | G29: FATURADO | H29: BACKLOG | I29: =IF(A29="","",IFERROR(VLOOKUP(TEXT(A29,"0"),#REF!,9,FALSE),"")) | K29: =IFERROR(INDEX(#REF!,MATCH(A29,#REF!,0)),"") | L29: =IFERROR(INDEX(SKU!E:E,MATCH(B29,SKU!C:C,0)),"") -> ALBERT EINSTEIN | R29: =IF(COUNTIF(ROMANEIOS!K:K,A29)>0,J29,"")
A30: =IFERROR(INDEX(NFS!F:F,MATCH(B30,NFS!E:E,0)),"") -> 178999 | B30: 69149 | C30: WELINGTON | D30: 46304 | E30: =IF(B30="","",COUNTIF(SKU!C:C,B30)) -> 1 | F30: CARRO PROPRIO | G30: FATURADO | H30: BACKLOG | I30: =IF(A30="","",IFERROR(VLOOKUP(TEXT(A30,"0"),#REF!,9,FALSE),"")) | K30: =IFERROR(INDEX(#REF!,MATCH(A30,#REF!,0)),"") | L30: =IFERROR(INDEX(SKU!E:E,MATCH(B30,SKU!C:C,0)),"") -> ALBERT EINSTEIN | R30: =IF(COUNTIF(ROMANEIOS!K:K,A30)>0,J30,"")
A31: =IFERROR(INDEX(NFS!F:F,MATCH(B31,NFS!E:E,0)),"") -> 178869 | B31: 69464 | C31: LEANDRO | D31: 46302 | E31: =IF(B31="","",COUNTIF(SKU!C:C,B31)) -> 2 | F31: BROS | G31: FATURADO | H31: SAUDAVEL | I31: =IF(A31="","",IFERROR(VLOOKUP(TEXT(A31,"0"),#REF!,9,FALSE),"")) | K31: =IFERROR(INDEX(#REF!,MATCH(A31,#REF!,0)),"") | L31: =IFERROR(INDEX(SKU!E:E,MATCH(B31,SKU!C:C,0)),"") -> DASA CUIABA | R31: =IF(COUNTIF(ROMANEIOS!K:K,A31)>0,J31,"")
A32: =IFERROR(INDEX(NFS!F:F,MATCH(B32,NFS!E:E,0)),"") -> 179015 | B32: 69351 | C32: WELINGTON | D32: 46304 | E32: =IF(B32="","",COUNTIF(SKU!C:C,B32)) -> 7 | F32: CARRO PROPRIO | G32: FATURADO | H32: BACKLOG | I32: =IF(A32="","",IFERROR(VLOOKUP(TEXT(A32,"0"),#REF!,9,FALSE),"")) | K32: =IFERROR(INDEX(#REF!,MATCH(A32,#REF!,0)),"") | L32: =IFERROR(INDEX(SKU!E:E,MATCH(B32,SKU!C:C,0)),"") -> ALBERT EINSTEIN | R32: =IF(COUNTIF(ROMANEIOS!K:K,A32)>0,J32,"")
A33: =IFERROR(INDEX(NFS!F:F,MATCH(B33,NFS!E:E,0)),"") -> 179039 | B33: 69437 | C33: WELINGTON | D33: 46304 | E33: =IF(B33="","",COUNTIF(SKU!C:C,B33)) -> 7 | F33: CARRO PROPRIO | G33: FATURADO | H33: BACKLOG | I33: =IF(A33="","",IFERROR(VLOOKUP(TEXT(A33,"0"),#REF!,9,FALSE),"")) | K33: =IFERROR(INDEX(#REF!,MATCH(A33,#REF!,0)),"") | L33: =IFERROR(INDEX(SKU!E:E,MATCH(B33,SKU!C:C,0)),"") -> ALBERT EINSTEIN | R33: =IF(COUNTIF(ROMANEIOS!K:K,A33)>0,J33,"")
A34: =IFERROR(INDEX(NFS!F:F,MATCH(B34,NFS!E:E,0)),"") -> 178880 | B34: 69016 | C34: SANDRO | D34: 46303 | E34: 1 | F34: CARRO PROPRIO | G34: FATURADO | H34: SAUDAVEL | I34: =IF(A34="","",IFERROR(VLOOKUP(TEXT(A34,"0"),#REF!,9,FALSE),"")) | K34: =IFERROR(INDEX(#REF!,MATCH(A34,#REF!,0)),"") | L34: SOCIEDADE BENEF ISRAELITABRAS HOSP ALBER | R34: =IF(COUNTIF(ROMANEIOS!K:K,A34)>0,J34,"")
A35: =IFERROR(INDEX(NFS!F:F,MATCH(B35,NFS!E:E,0)),"") -> 178943 | B35: 69324 | C35: SANDRO | D35: 46303 | E35: =IF(B35="","",COUNTIF(SKU!C:C,B35)) -> 5 | F35: BTA | G35: FATURADO | H35: SAUDAVEL | I35: =IF(A35="","",IFERROR(VLOOKUP(TEXT(A35,"0"),#REF!,9,FALSE),"")) | K35: =IFERROR(INDEX(#REF!,MATCH(A35,#REF!,0)),"") | L35: =IFERROR(INDEX(SKU!E:E,MATCH(B35,SKU!C:C,0)),"") -> DASA GOIANIA | R35: =IF(COUNTIF(ROMANEIOS!K:K,A35)>0,J35,"")
A36: =IFERROR(INDEX(NFS!F:F,MATCH(B36,NFS!E:E,0)),"") | B36: 69215 | C36: JOÃO PAULO | D36: 46303 | E36: 1 | F36: CARRO PROPRIO | G36: CONFERIDO | H36: SAUDAVEL | I36: =IF(A36="","",IFERROR(VLOOKUP(TEXT(A36,"0"),#REF!,9,FALSE),"")) | K36: =IFERROR(INDEX(#REF!,MATCH(A36,#REF!,0)),"") | L36: SOCIEDADE BENEF ISRAELITABRAS HOSP ALBER | R36: =IF(COUNTIF(ROMANEIOS!K:K,A36)>0,J36,"") -> 0
A37: =IFERROR(INDEX(NFS!F:F,MATCH(B37,NFS!E:E,0)),"") -> 178872 | B37: 69195 | C37: JOÃO PAULO | D37: 46303 | E37: =IF(B37="","",COUNTIF(SKU!C:C,B37)) -> 1 | F37: CARRO PROPRIO | G37: FATURADO | H37: SAUDAVEL | I37: =IF(A37="","",IFERROR(VLOOKUP(TEXT(A37,"0"),#REF!,9,FALSE),"")) | K37: =IFERROR(INDEX(#REF!,MATCH(A37,#REF!,0)),"") | L37: =IFERROR(INDEX(SKU!E:E,MATCH(B37,SKU!C:C,0)),"") -> SIRIO LIBANES | R37: =IF(COUNTIF(ROMANEIOS!K:K,A37)>0,J37,"")
A38: =IFERROR(INDEX(NFS!F:F,MATCH(B38,NFS!E:E,0)),"") -> 178874 | B38: 69194 | C38: JOÃO PAULO | D38: 46303 | E38: =IF(B38="","",COUNTIF(SKU!C:C,B38)) -> 2 | F38: CARRO PROPRIO | G38: FATURADO | H38: SAUDAVEL | I38: =IF(A38="","",IFERROR(VLOOKUP(TEXT(A38,"0"),#REF!,9,FALSE),"")) | K38: =IFERROR(INDEX(#REF!,MATCH(A38,#REF!,0)),"") | L38: =IFERROR(INDEX(SKU!E:E,MATCH(B38,SKU!C:C,0)),"") -> SIRIO LIBANES | R38: =IF(COUNTIF(ROMANEIOS!K:K,A38)>0,J38,"")
A39: =IFERROR(INDEX(NFS!F:F,MATCH(B39,NFS!E:E,0)),"") -> 178968 | B39: 69040 | C39: JOÃO PAULO | D39: 46303 | E39: =IF(B39="","",COUNTIF(SKU!C:C,B39)) -> 3 | F39: CARRO PROPRIO | G39: FATURADO | H39: SAUDAVEL | I39: =IF(A39="","",IFERROR(VLOOKUP(TEXT(A39,"0"),#REF!,9,FALSE),"")) | K39: =IFERROR(INDEX(#REF!,MATCH(A39,#REF!,0)),"") | L39: =IFERROR(INDEX(SKU!E:E,MATCH(B39,SKU!C:C,0)),"") -> ALBERT EINSTEIN | R39: =IF(COUNTIF(ROMANEIOS!K:K,A39)>0,J39,"")
A40: =IFERROR(INDEX(NFS!F:F,MATCH(B40,NFS!E:E,0)),"") | B40: 68942 | C40: JOÃO PAULO | D40: 46303 | E40: =IF(B40="","",COUNTIF(SKU!C:C,B40)) -> 1 | F40: CARRO PROPRIO | G40: SEPARANDO | H40: SAUDAVEL | I40: =IF(A40="","",IFERROR(VLOOKUP(TEXT(A40,"0"),#REF!,9,FALSE),"")) | K40: =IFERROR(INDEX(#REF!,MATCH(A40,#REF!,0)),"") | L40: =IFERROR(INDEX(SKU!E:E,MATCH(B40,SKU!C:C,0)),"") -> HOSP INFANTIL SABARA | R40: =IF(COUNTIF(ROMANEIOS!K:K,A40)>0,J40,"") -> 0
...

Sheet NFS
A1: Filial | B1: EmissÃ£o | C1: Cliente | D1: Nome Fantasia | E1: PV | F1: Nr.NF | G1: Serie | H1: R$ Merc. | I1: Chave | J1: Cod.Transp. | K1: Transportador | L1: Tp.Frete | M1: % Frete | N1: CC-e
A2: 101 | B2: 46237 | C2: 000020-104 | D2: DASA HOSP 9 DE JULHO | E2: 64211 | F2: 172826 | G2: 1 | H2: 21998.76 | I2: 3.5260812e+43 | J2: 32 | K2: CARRO PROPRIO | L2: C
A3: 101 | B3: 46237 | C3: 000111-001 | D3: DASA INNOVA HOSP | E3: 63932 | F3: 172827 | G3: 1 | H3: 1108.1 | I3: 3.5260812e+43 | J3: 32 | K3: CARRO PROPRIO | L3: C
A4: 101 | B4: 46237 | C4: 000024-003 | D4: ALBERT EINSTEIN | E4: 62391 | F4: 172828 | G4: 1 | H4: 200.43 | I4: 3.5260812e+43 | J4: 32 | K4: CARRO PROPRIO | L4: C
A5: 101 | B5: 46237 | C5: 000060-001 | D5: HOSP SANTA CATARINA | E5: 64184 | F5: 172832 | G5: 1 | H5: 31942.95 | I5: 3.5260812e+43 | J5: 32 | K5: CARRO PROPRIO | L5: C
A6: 101 | B6: 46237 | C6: 000024-002 | D6: ALBERT EINSTEIN | E6: 60104 | F6: 172833 | G6: 1 | H6: 42997.5 | I6: 3.5260812e+43 | J6: 32 | K6: CARRO PROPRIO | L6: C
A7: 101 | B7: 46237 | C7: 000034-001 | D7: OSWALDO CRUZ SP | E7: 64082 | F7: 172834 | G7: 1 | H7: 9686.38 | I7: 3.5260812e+43 | J7: 32 | K7: CARRO PROPRIO | L7: C
A8: 101 | B8: 46237 | C8: 000020-178 | D8: DASA SSZ 45.796.554/ | E8: 63737 | F8: 172835 | G8: 1 | H8: 6093.68 | I8: 3.5260812e+43 | J8: 32 | K8: CARRO PROPRIO | L8: C
A9: 101 | B9: 46237 | C9: 001240-007 | D9: SIRIO LIBANES | E9: 63646 | F9: 172836 | G9: 1 | H9: 41324.5 | I9: 3.5260812e+43 | J9: 32 | K9: CARRO PROPRIO | L9: C
A10: 101 | B10: 46237 | C10: 001240-007 | D10: SIRIO LIBANES | E10: 63929 | F10: 172837 | G10: 1 | H10: 24737.36 | I10: 3.5260812e+43 | J10: 32 | K10: CARRO PROPRIO | L10: C
A11: 101 | B11: 46237 | C11: 001240-007 | D11: SIRIO LIBANES | E11: 63742 | F11: 172838 | G11: 1 | H11: 19361.62 | I11: 3.5260812e+43 | J11: 32 | K11: CARRO PROPRIO | L11: C
A12: 101 | B12: 46237 | C12: 001240-007 | D12: SIRIO LIBANES | E12: 64141 | F12: 172839 | G12: 1 | H12: 22374.6 | I12: 3.5260812e+43 | J12: 32 | K12: CARRO PROPRIO | L12: C
A13: 101 | B13: 46237 | C13: 001240-007 | D13: SIRIO LIBANES | E13: 54836 | F13: 172840 | G13: 1 | H13: 4500 | I13: 3.5260812e+43 | J13: 32 | K13: CARRO PROPRIO | L13: C
... A41: 101 | B41: 46238 | C41: 000024-003 | D41: ALBERT EINSTEIN | E41: 63977 | F41: 172871 | G41: 1 | H41: 359.7 | I41: 3.5260812e+43 | J41: 32 | K41: CARRO PROPRIO | L41: C
A42: 101 | B42: 46238 | C42: 000064-020 | D42: SERVI SOCIAL SECONCI | E42: 63938 | F42: 172872 | G42: 1 | H42: 5855.31 | I42: 3.5260812e+43 | J42: 7 | K42: RISSO | L42: C | N42: X
A43: 101 | B43: 46238 | C43: 000020-177 | D43: DASA 61.486.650/1161 | E43: 64252 | F43: 172874 | G43: 1 | H43: 2076.31 | I43: 3.5260812e+43 | J43: 32 | K43: CARRO PROPRIO | L43: C
A44: 101 | B44: 46238 | C44: 000024-003 | D44: ALBERT EINSTEIN | E44: 63976 | F44: 172875 | G44: 1 | H44: 359.7 | I44: 3.5260812e+43 | J44: 32 | K44: CARRO PROPRIO | L44: C
A45: 101 | B45: 46238 | C45: 000064-015 | D45: CHS REG SOROCABA | E45: 64255 | F45: 172876 | G45: 1 | H45: 1145.6 | I45: 3.5260812e+43 | J45: 7 | K45: RISSO | L45: C
A46: 101 | B46: 46238 | C46: 000070-008 | D46: TECNOLAB UNID VIII | E46: 64272 | F46: 172877 | G46: 1 | H46: 1062.6 | I46: 3.5260812e+43 | J46: 32 | K46: CARRO PROPRIO | L46: C
A47: 101 | B47: 46238 | C47: 000894-001 | D47: HOSP SAO VICENTE | E47: 64266 | F47: 172878 | G47: 1 | H47: 525.45 | I47: 3.5260812e+43 | J47: 32 | K47: CARRO PROPRIO | L47: C
A48: 101 | B48: 46238 | C48: 000921-001 | D48: HOSP PROF EDMUNDO VA | E48: 64188 | F48: 172879 | G48: 1 | H48: 886.1 | I48: 3.5260812e+43 | J48: 32 | K48: CARRO PROPRIO | L48: C
A49: 101 | B49: 46238 | C49: 001435-001 | D49: HOSP NIPO BRASILEIRO | E49: 63669 | F49: 172880 | G49: 1 | H49: 10512 | I49: 3.5260812e+43 | J49: 32 | K49: CARRO PROPRIO | L49: C
A50: 101 | B50: 46238 | C50: 001854-001 | D50: CLEANING SOLUTIONS C | E50: 64359 | F50: 172881 | G50: 1 | H50: 1494.85 | I50: 3.5260812e+43 | J50: 32 | K50: CARRO PROPRIO | L50: C
A51: 101 | B51: 46238 | C51: 000024-003 | D51: ALBERT EINSTEIN | E51: 63892 | F51: 172882 | G51: 1 | H51: 1654.35 | I51: 3.5260812e+43 | J51: 32 | K51: CARRO PROPRIO | L51: C
A52: 101 | B52: 46238 | C52: 000049-001 | D52: HOSPITAL MORIAH 19.0 | E52: 63393 | F52: 172883 | G52: 1 | H52: 4402.71 | I52: 3.5260812e+43 | J52: 32 | K52: CARRO PROPRIO | L52: C
A53: 101 | B53: 46238 | C53: 000064-002 | D53: SECONCI MATARAZZO | E53: 64084 | F53: 172884 | G53: 1 | H53: 445.5 | I53: 3.5260812e+43 | J53: 32 | K53: CARRO PROPRIO | L53: C
A54: 101 | B54: 46238 | C54: 000064-002 | D54: SECONCI MATARAZZO | E54: 64145 | F54: 172885 | G54: 1 | H54: 123.1 | I54: 3.5260812e+43 | J54: 32 | K54: CARRO PROPRIO | L54: C
... A60: 101 | B60: 46239 | C60: 000894-001 | D60: HOSP SAO VICENTE | E60: 64404 | F60: 172891 | G60: 1 | H60: 3450 | I60: 3.5260812e+43 | J60: 32 | K60: CARRO PROPRIO | L60: C
A61: 101 | B61: 46239 | C61: 000894-001 | D61: HOSP SAO VICENTE | E61: 64265 | F61: 172892 | G61: 1 | H61: 3065.54 | I61: 3.5260812e+43 | J61: 32 | K61: CARRO PROPRIO | L61: C | N61: X
A62: 101 | B62: 46239 | C62: 000894-001 | D62: HOSP SAO VICENTE | E62: 64267 | F62: 172893 | G62: 1 | H62: 242.73 | I62: 3.5260812e+43 | J62: 32 | K62: CARRO PROPRIO | L62: C
A63: 101 | B63: 46239 | C63: 000894-001 | D63: HOSP SAO VICENTE | E63: 64177 | F63: 172894 | G63: 1 | H63: 256.24 | I63: 3.5260812e+43 | J63: 32 | K63: CARRO PROPRIO | L63: C | N63: X
A64: 101 | B64: 46239 | C64: 000894-001 | D64: HOSP SAO VICENTE | E64: 64186 | F64: 172895 | G64: 1 | H64: 705.35 | I64: 3.5260812e+43 | J64: 32 | K64: CARRO PROPRIO | L64: C
A65: 101 | B65: 46239 | C65: 000894-001 | D65: HOSP SAO VICENTE | E65: 64171 | F65: 172896 | G65: 1 | H65: 520.77 | I65: 3.5260812e+43 | J65: 32 | K65: CARRO PROPRIO | L65: C
A66: 101 | B66: 46239 | C66: 000894-001 | D66: HOSP SAO VICENTE | E66: 64176 | F66: 172897 | G66: 1 | H66: 104.24 | I66: 3.5260812e+43 | J66: 32 | K66: CARRO PROPRIO | L66: C | N66: X
A67: 101 | B67: 46239 | C67: 000894-001 | D67: HOSP SAO VICENTE | E67: 64170 | F67: 172898 | G67: 1 | H67: 104.93 | I67: 3.5260812e+43 | J67: 32 | K67: CARRO PROPRIO | L67: C
A68: 101 | B68: 46239 | C68: 000894-001 | D68: HOSP SAO VICENTE | E68: 64172 | F68: 172899 | G68: 1 | H68: 137.91 | I68: 3.5260812e+43 | J68: 32 | K68: CARRO PROPRIO | L68: C | N68: X
A69: 101 | B69: 46239 | C69: 000894-001 | D69: HOSP SAO VICENTE | E69: 64173 | F69: 172900 | G69: 1 | H69: 763.37 | I69: 3.5260812e+43 | J69: 32 | K69: CARRO PROPRIO | L69: C | N69: X
A70: 101 | B70: 46239 | C70: 000894-001 | D70: HOSP SAO VICENTE | E70: 64245 | F70: 172901 | G70: 1 | H70: 424.98 | I70: 3.5260812e+43 | J70: 32 | K70: CARRO PROPRIO | L70: C
A71: 101 | B71: 46239 | C71: 000894-001 | D71: HOSP SAO VICENTE | E71: 64254 | F71: 172902 | G71: 1 | H71: 15558.77 | I71: 3.5260812e+43 | J71: 32 | K71: CARRO PROPRIO | L71: C | N71: X
A72: 101 | B72: 46239 | C72: 000894-001 | D72: HOSP SAO VICENTE | E72: 64174 | F72: 172903 | G72: 1 | H72: 114.55 | I72: 3.5260812e+43 | J72: 32 | K72: CARRO PROPRIO | L72: C
...

Sheet ROMANEIOS
A1: 11260 - | | | B1: 46174 | C1: CORREIOS | E1: CORREIO | F1: Filial | G1: Emissão | H1: Cliente - Loja | I1: Nome Fantasia | J1: Num.PV | K1: Num.NF | L1: Vl.NF | M1: Dt.Entrega
F2: 101 | G2: 46171 | H2: 000020 - 177 | I2: DASA 61.486.650/1161 | J2: 59434 | K2: 167718 | L2: 17276.16 | M2: 46175
F3: 101 | G3: 46171 | H3: 000036 - 003 | I3: HAPVIDA | L3: 11024.76

Sheet SEPARADORES
A1: Separadores
A2: BRADOCK
A3: JOÃO PAULO
A4: LEANDRO
A5: GLEICE
A6: PEDRO H.
A7: RAONI
A8: MIJOHNSON
A9: ALEX
A10: JOÃO OLIVEIRA
A11: JESSICA
A12: VANESSA
... A38: SAUDAVEL

Sheet DINÂMICA
A1: SEPARADOR | B1: DATA | C1: Contagem de NF | D1: Soma de SKU'S | E1: Soma de VOLUMES | F1: Soma de PALETES
A2: JOÃO PAULO | C2: 10 | D2: 69 | E2: 0
A3: LEANDRO | C3: 38 | D3: 131 | E3: 0
A4: RAONI | C4: 26 | D4: 52 | E4: 0
A5: (vazio) | C5: 6899 | D5: 0 | E5: 0 | F5: 0
A6: PAIVA | C6: 7 | D6: 45 | E6: 0
A7: RAPHAEL | C7: 26 | D7: 142 | E7: 0 | F7: 0
A8: IVAN | C8: 10 | D8: 10 | E8: 0
A9: MTC | C9: 1 | D9: 1
A10: CLAUDIO | B10: 46302 | C10: 2 | D10: 10
B11: 46304 | C11: 8 | D11: 17 | E11: 0
A12: CLAUDIO Total | C12: 10 | D12: 27 | E12: 0
A13: MARCOS | B13: 46302 | C13: 1 | D13: 6
B14: 46303 | C14: 4 | D14: 23 | E14: 0
B15: 46304 | C15: 1 | D15: 1 | E15: 0
A16: MARCOS Total | C16: 6 | D16: 30 | E16: 0
A17: MAURICIO | B17: 46302 | C17: 3 | D17: 47 | E17: 0
B18: 46303 | C18: 5 | D18: 77 | E18: 0
B19: 46304 | C19: 6 | D19: 18 | E19: 0
B20: 46305 | C20: 10 | D20: 46 | E20: 0
B21: 46306 | C21: 8 | D21: 5 | E21: 0
A22: MAURICIO Total | C22: 32 | D22: 193 | E22: 0
A23: ANDRE SOUZA | B23: 46302 | C23: 5 | D23: 8 | E23: 0
B24: 46303 | C24: 6 | D24: 10 | E24: 0
A25: ANDRE SOUZA Total | C25: 11 | D25: 18 | E25: 0
A26: WELINGTON | B26: 46302 | C26: 1 | D26: 41 | E26: 0
B27: 46303 | C27: 7 | D27: 29 | E27: 0
B28: 46304 | C28: 7 | D28: 23 | E28: 0
B29: 46305 | C29: 23 | D29: 31 | E29: 0
A30: WELINGTON Total | C30: 38 | D30: 124 | E30: 0
A31: MATHEUS | B31: 46302 | C31: 1 | D31: 1 | E31: 0
B32: 46304 | C32: 3 | D32: 8 | E32: 0
A33: MATHEUS Total | C33: 4 | D33: 9 | E33: 0
A34: SANDRO | B34: 46303 | C34: 2 | D34: 6 | E34: 0
B35: 46304 | C35: 4 | D35: 10 | E35: 0
A36: SANDRO Total | C36: 6 | D36: 16 | E36: 0
A37: KARINA | B37: 46303 | C37: 15 | D37: 20 | E37: 0
B38: 46304 | C38: 1 | D38: 1 | E38: 0
A39: KARINA Total | C39: 16 | D39: 21 | E39: 0
A40: JESSICA | B40: 46303 | C40: 1 | D40: 5 | E40: 0
...

Sheet SKU
A1: Filial | B1: EmissÃ£o | C1: Pedido | D1: Cliente-Loja | E1: Nome Fantasia | F1: Produto | G1: DescriÃ§Ã£o | H1: Qtd.Original | I1: Qtd. | J1: R$ Vda. | K1: Classe | L1: TES | M1: Armz.
A2: 101 | B2: 46153 | C2: 58116 | D2: 000125-001 | E2: SOLUTION BELA VISTA | F2: 160001 | G2: BASE SELADORA ACRILICA SEALER 5L | H2: 4 | I2: 0 | J2: 345.86 | K2: 9003 | L2: 561 | M2: 1
A3: 101 | B3: 46153 | C3: 58116 | D3: 000125-001 | E3: SOLUTION BELA VISTA | F3: 280382 | G3: CERA FANTASTIC HIGH GLOSS 5L | H3: 4 | I3: 0 | J3: 365.4 | K3: 9003 | L3: 717 | M3: 1
A4: 101 | B4: 46181 | C4: 60105 | D4: 000024-002 | E4: ALBERT EINSTEIN | F4: 15196 | G4: AVENTAL PREMIUM COM PUNHO EM MALHA REF.1360 | H4: 35000 | I4: 0 | J4: 122850 | K4: 9003 | L4: 501 | M4: 1
A5: 101 | B5: 46195 | C5: 61413 | D5: 000007-001 | E5: AMOEDO | F5: 15400 | G5: SACO HAMPER AZUL ROLO S/ CORDAO 80X100X0.06 C/50 | H5: 1 | I5: 0 | J5: 26.24 | K5: 9003 | L5: 722 | M5: 1
A6: 101 | B6: 46206 | C6: 62288 | D6: 000011-001 | E6: BENEFICENCIA SP | F6: 14710 | G6: LUVA P/BANHO C/5 | H6: 6000 | I6: 0 | J6: 11700 | K6: 9003 | L6: 501 | M6: 1
A7: 101 | B7: 46217 | C7: 62906 | D7: 000792-001 | E7: C B C | F7: 190229 | G7: REFIL MOPINHO AZUL PONTA CORTADA 30CM | H7: 187 | I7: 2 | J7: 5095.75 | K7: 9003 | L7: 501 | M7: 1
A8: 101 | B8: 46225 | C8: 63681 | D8: 003595-001 | E8: SIDE | F8: 15420 | G8: SABAO EM PO 800G | H8: 2 | I8: 0 | J8: 38.4 | L8: 507 | M8: 1
A9: 101 | B9: 46225 | C9: 63681 | D9: 003595-001 | E9: SIDE | F9: 60007 | G9: FLANELA BRANCA 40X60CM | H9: 6 | I9: 0 | J9: 15.54 | K9: 9003 | L9: 501 | M9: 1
A10: 101 | B10: 46225 | C10: 63681 | D10: 003595-001 | E10: SIDE | F10: 60008 | G10: PANO SACO ALVEJADO 45X65 | H10: 10 | I10: 0 | J10: 47 | K10: 9003 | L10: 501 | M10: 1
A11: 101 | B11: 46225 | C11: 63681 | D11: 003595-001 | E11: SIDE | F11: 70130 | G11: LUVA TOP VERDE M | H11: 4 | I11: 0 | J11: 40.8 | K11: 9003 | L11: 802 | M11: 1
A12: 101 | B12: 46225 | C12: 63681 | D12: 003595-001 | E12: SIDE | F12: 70151 | G12: LUVA PLUS LARANJA P | H12: 2 | I12: 0 | J12: 19.8 | L12: 802 | M12: 1
A13: 101 | B13: 46225 | C13: 63681 | D13: 003595-001 | E13: SIDE | F13: 70152 | G13: LUVA PLUS LARANJA M | H13: 3 | I13: 0 | J13: 29.7 | L13: 802 | M13: 1
A14: 101 | B14: 46225 | C14: 63681 | D14: 003595-001 | E14: SIDE | F14: 70153 | G14: LUVA PLUS LARANJA G | H14: 2 | I14: 0 | J14: 19.8 | L14: 802 | M14: 1
A15: 101 | B15: 46225 | C15: 63681 | D15: 003595-001 | E15: SIDE | F15: 80119 | G15: SABAO EM PEDRA 160G GLICERINADO C/5 | H15: 6 | I15: 0 | J15: 98.82 | K15: 9003 | L15: 501 | M15: 1
A16: 101 | B16: 46225 | C16: 63681 | D16: 003595-001 | E16: SIDE | F16: 80358 | G16: DETERGENTE AGIPRO CLEENE 5L | H16: 1 | I16: 0 | J16: 33.83 | K16: 9003 | L16: 507 | M16: 1
A17: 101 | B17: 46225 | C17: 63681 | D17: 003595-001 | E17: SIDE | F17: 160039 | G17: MULTIUSO STAR GLASS 5L | H17: 2 | I17: 0 | J17: 97 | K17: 9003 | L17: 507 | M17: 1
A18: 101 | B18: 46225 | C18: 63681 | D18: 003595-001 | E18: SIDE | F18: 160049 | G18: DESENGRAXANTE CLEAN GREASE 5L | H18: 2 | I18: 0 | J18: 150 | K18: 9003 | L18: 507 | M18: 1
A19: 101 | B19: 46225 | C19: 63681 | D19: 003595-001 | E19: SIDE | F19: 160054 | G19: DESINFETANTE ALGAS MARINHAS VERSATIL 5L | H19: 1 | I19: 0 | J19: 34.88 | K19: 9003 | L19: 501 | M19: 1
A20: 101 | B20: 46225 | C20: 63681 | D20: 003595-001 | E20: SIDE | F20: 170106 | G20: ESPONJA SB NAO RISCA AZUL SCOTCH | H20: 15 | I20: 0 | J20: 46.5 | K20: 9003 | L20: 507 | M20: 1
A21: 101 | B21: 46225 | C21: 63681 | D21: 003595-001 | E21: SIDE | F21: 260021 | G21: HIPOCLORITO 5% BUTTERFLY 5L | H21: 1 | I21: 0 | J21: 23.48 | K21: 9003 | L21: 501 | M21: 1
A22: 101 | B22: 46225 | C22: 63681 | D22: 003595-001 | E22: SIDE | F22: 280707 | G22: PULVERIZADOR 500ML PERSONALIZADO MULTIUSO | H22: 2 | I22: 0 | J22: 12.1 | K22: 9003 | L22: 501 | M22: 1
A23: 101 | B23: 46225 | C23: 63681 | D23: 003595-001 | E23: SIDE | F23: 280710 | G23: PULVERIZADOR 500ML PERSONALIZADO DESINFETANTE | H23: 2 | I23: 0 | J23: 12.1 | K23: 9003 | L23: 501 | M23: 1
A24: 101 | B24: 46225 | C24: 63717 | D24: 000003-023 | E24: AFIP | F24: 15744 | G24: ENV PLAST PELBD TRANSP IMP ESPECIMES | H24: 20000 | I24: 0 | J24: 16400 | K24: 9003 | L24: 501 | M24: 1
A25: 101 | B25: 46227 | C25: 63892 | D25: 000024-003 | E25: ALBERT EINSTEIN | F25: 170064 | G25: FIBRA DE LIMPEZA PESADA VERDE 102X230 | H25: 100 | I25: 0 | J25: 314 | K25: 9003 | L25: 501 | M25: 1
A26: 101 | B26: 46232 | C26: 64084 | D26: 000064-002 | E26: SECONCI MATARAZZO | F26: 170067 | G26: DISCO LIMPADOR VERDE 410MM | H26: 3 | I26: 0 | J26: 93.36 | K26: 9003 | L26: 501 | M26: 1
A27: 101 | B27: 46238 | C27: 64354 | D27: 000001-001 | E27: MASTER HIGIMED SP | F27: 80201 | G27: ODORIZADOR TALCO 360ML | H27: 2 | I27: 0 | J27: 26.86 | L27: 682 | M27: 1
A28: 101 | B28: 46239 | C28: 64514 | D28: 000894-001 | E28: HOSP SAO VICENTE | F28: 120238 | G28: DISPENSER AUTO CORTE FUME 23CM ELISA | H28: 10 | I28: 0 | J28: 2328.4 | K28: 9003 | L28: 909 | M28: 1
A29: 101 | B29: 46240 | C29: 64673 | D29: 002422-002 | E29: GUIMA CONSECO | F29: 170009 | G29: FLEX LIMPA BANHEIROS 4B | H29: 3 | I29: 0 | J29: 1526.04 | K29: 9003 | L29: 501 | M29: 1
A30: 101 | B30: 46241 | C30: 64819 | D30: 000043-007 | E30: LIDERANCA DF | F30: 10016 | G30: ALCOOL 70 1L | H30: 1 | I30: 1 | J30: 7.25 | K30: 9003 | L30: 501 | M30: 1
A31: 101 | B31: 46241 | C31: 64819 | D31: 000043-007 | E31: LIDERANCA DF | F31: 30220 | G31: SACO P/ LIXO PRETO 60L 60X70 LEVE | H31: 2 | I31: 2 | J31: 32.5 | K31: 9003 | L31: 501 | M31: 1
A32: 101 | B32: 46241 | C32: 64819 | D32: 000043-007 | E32: LIDERANCA DF | F32: 60001 | G32: PANO SACO ALVEJADO G 40X65 | H32: 3 | I32: 3 | J32: 7.95 | K32: 9003 | L32: 501 | M32: 1
A33: 101 | B33: 46241 | C33: 64819 | D33: 000043-007 | E33: LIDERANCA DF | F33: 60007 | G33: FLANELA BRANCA 40X60CM | H33: 3 | I33: 3 | J33: 4.47 | K33: 9003 | L33: 501 | M33: 1
A34: 101 | B34: 46241 | C34: 64819 | D34: 000043-007 | E34: LIDERANCA DF | F34: 70067 | G34: LUVA SOFT VERDE M | H34: 1 | I34: 1 | J34: 5.6 | K34: 9003 | L34: 802 | M34: 1
A35: 101 | B35: 46241 | C35: 64819 | D35: 000043-007 | E35: LIDERANCA DF | F35: 70126 | G35: LUVA TOP AMARELA M | H35: 1 | I35: 1 | J35: 5.6 | K35: 9003 | L35: 802 | M35: 1
A36: 101 | B36: 46241 | C36: 64819 | D36: 000043-007 | E36: LIDERANCA DF | F36: 130008 | G36: TOUCA BRANCA SANFONADA C/ 100 | H36: 1 | I36: 1 | J36: 11.02 | K36: 9003 | L36: 501 | M36: 1
A37: 101 | B37: 46241 | C37: 64819 | D37: 000043-007 | E37: LIDERANCA DF | F37: 160005 | G37: DETERGENTE BECKPLATER CONCENTO 5L | H37: 1 | I37: 1 | J37: 38.73 | K37: 9003 | L37: 501 | M37: 1
A38: 101 | B38: 46241 | C38: 64819 | D38: 000043-007 | E38: LIDERANCA DF | F38: 160048 | G38: CLOREX USO HOSPITALAR 5L | H38: 1 | I38: 1 | J38: 29.43 | K38: 9003 | L38: 501 | M38: 1
A39: 101 | B39: 46241 | C39: 64819 | D39: 000043-007 | E39: LIDERANCA DF | F39: 170028 | G39: FIBRA DE LIMPEZA GERAL VERDE 102X230 | H39: 3 | I39: 3 | J39: 3.63 | K39: 9003 | L39: 501 | M39: 1
A40: 101 | B40: 46241 | C40: 64819 | D40: 000043-007 | E40: LIDERANCA DF | F40: 170052 | G40: DISCO LIMPADOR VERDE 440MM | H40: 1 | I40: 1 | J40: 21.75 | L40: 501 | M40: 1
...

Sheet Transportes
A2: TJB
A3: BTA
A4: RISSO
A5: LEOFRAN
A6: ARLETE
A7: PACIFICO
A8: BROS
A9: RIO VERMELHO
A10: SCHREIBERLOG
A11: CARRO PROPRIO
A12: RETIRA
A13: TECNICA
... A17: CORREIOS

Sheet MOTIVOS ERROS
A1: Motivos
A2: Divergência materiais
A3: Divergência quantidades
A4: Divergência de materiais e quantidade
A6: PAULO
A7: SANDRO
A8: LEANDRO
A9: RAONI
A10: HIGOR
A11: PEDRO HENRIQUE
A12: ROBSON
A13: DAVID
... A17: RAPHAEL
A19: 1
A20: 2
A21: 3
F22: CLIENTE
A23: DIVERGÊNCIA NF X OC CLIENTE | F23: COMERCIAL
A24: DIVERGÊNCIA DE MAT. | F24: LOGISTICA
A25: DIVERGÊNCIA DE QTD. | F25: TRANSPORTADORA
A26: DIVERGENCIA DE MAT. E QTD
A27: FORA DA DATA PROGRAMADA (ANTECIPADO)
A28: FORA DA DATA PROGRAMADA (ATRASO)
A29: FALTA DE AGENDAMENTO
A30: MATERIAIS AVARIADOS
A31: REGULARIZAÇÃO TJ
A32: ENDEREÇO NÃO LOCALIZADO
A33: ENDEREÇO INCORRETO
A34: FORA DO HORARIO DE RECEBIMENTO
A35: FORA DO HORARIO DE RECEBIMENTO (DESTACADO EM NF)
A36: DUPLICIDADE
A37: MATERIAIS VENCIDOS
... A79: AGUARDANDO CONFERÊNCIA

Sheet MATERIAIS
A1: CODIGO | B1: DESCRIÇÃO | C1: MARCA
A2: 10009 | B2: DESINFETANTE EUCALIPTO 5L | C2: DVISAO
A3: 10009 | B3: DESINFETANTE EUCALIPTO 5L | C3: DVISAO
A4: 10009 | B4: DESINFETANTE EUCALIPTO 5L | C4: DVISAO
A5: 10009 | B5: DESINFETANTE EUCALIPTO 5L | C5: DVISAO
A6: 10010 | B6: DESINFETANTE LAVANDA 5L | C6: DVISAO
A7: 10010 | B7: DESINFETANTE LAVANDA 5L | C7: DVISAO
A8: 10010 | B8: DESINFETANTE LAVANDA 5L | C8: DVISAO
A9: 10010 | B9: DESINFETANTE LAVANDA 5L | C9: DVISAO
A10: 10011 | B10: DETERGENTE NEUTRO 5L | C10: DVISAO
A11: 10011 | B11: DETERGENTE NEUTRO 5L | C11: DVISAO
A12: 10011 | B12: DETERGENTE NEUTRO 5L PP&CIA | C12: HARMONIEX
A13: 10011 | B13: DETERGENTE NEUTRO 5L | C13: DVISAO
A14: 10012 | B14: HIPOCLORITO 2.5% 5L | C14: CORDEX
A15: 10013 | B15: PANO MICROFIBRA 80X60 - LARANJA
A16: 10014 | B16: ALCOOL 99 1L | C16: SANTA CRUZ
A17: 10014 | B17: ALCOOL 99 1L | C17: SANTA CRUZ
A18: 10014 | B18: ALCOOL 99 1L | C18: SANTA CRUZ
A19: 10014 | B19: ALCOOL 99 1L | C19: SANTA CRUZ
A20: 10018 | B20: ALCOOL 70 100ML | C20: RICIE
A21: 10018 | B21: ALCOOL 70 100ML | C21: RICIE
A22: 10018 | B22: ALCOOL 70 100ML | C22: RICIE
A23: 10018 | B23: ALCOOL 70 100ML | C23: RICIE
A24: 10018 | B24: ALCOOL 70 100ML | C24: RICIE
A25: 10018 | B25: ALCOOL 70 100ML | C25: RICIE
A26: 10018 | B26: ALCOOL 70 100ML | C26: RICIE
A27: 10018 | B27: ALCOOL 70 100ML | C27: RICIE
... A31: 10024 | B31: AROMATIZANTE FLORAL 5L | C31: CORDEX
A32: 10034 | B32: ESSENCIA DE EUCALIPTO 1000ML
A33: 10034 | B33: ESSENCIA DE EUCALIPTO 1000ML
A34: 10059 | B34: ALCOOL GEL 70 500ML | C34: SANTA CRUZ
A35: 10059 | B35: ALCOOL GEL 70 500ML | C35: SANTA CRUZ
A36: 10059 | B36: ALCOOL GEL 70 500ML | C36: SANTA CRUZ
A37: 10060 | B37: ALCOOL GEL 70 500ML | C37: SAFRA
A38: 10063 | B38: HIPOCLORITO 12% 5L | C38: CORDEX
A39: 10064 | B39: POLIDOR METAL BRASS POLISH 1L | C39: SPARTAN
A40: 10064 | B40: POLIDOR METAL BRASS POLISH 1L | C40: SPARTAN
A41: 10064 | B41: POLIDOR METAL BRASS POLISH 1L | C41: SPARTAN
A42: 10064 | B42: POLIDOR METAL BRASS POLISH 1L | C42: SPARTAN
A43: 10077 | B43: SABONETE ESPUMA NEUTRO 400ML | C43: MASTER HIGIMED
...

Sheet DINAMICA
A1: SEPARADOR | B1: DATA | C1: Contagem de PV | D1: Soma de SKU'S
A2: ALEX | C2: 1 | D2: 3
A3: CLAUDIO | C3: 1 | D3: 2
A4: GLEICE | C4: 9 | D4: 33
A5: JESSICA | C5: 1 | D5: 10
A6: JOÃO OLIVEIRA | C6: 4 | D6: 16
A7: JOÃO PAULO | C7: 1 | D7: 4
A8: KARINA | C8: 8 | D8: 20
A9: MARIAH | C9: 12 | D9: 32
A10: MAURICIO | C10: 5 | D10: 24
A11: MIJOHNSON | C11: 1 | D11: 4
A12: RAPHAEL | C12: 6 | D12: 12
A13: MIRIÃ | C13: 9 | D13: 38
... A16: FELIPE | C16: 4 | D16: 22
A17: Total Geral | C17: 81 | D17: 291 | M17: =253-330 -> -77

Sheet GRAFICO

Sheet STATUS
A1: DATA | B1: BACKLOG | C1: SAUDAVEL | D1: MATERIAL FALTANDO | E1: NFS EMITIDAS
A2: 46302 | B2: =COUNTIFS(SEPARAÇÃO!$D:$D,A2,SEPARAÇÃO!$H:$H,"BACKLOG") -> 12 | C2: =COUNTIFS(SEPARAÇÃO!$D:$D,A2,SEPARAÇÃO!$H:$H,"saudavel") -> 18 | D2: =COUNTIFS(SEPARAÇÃO!$D:$D,A2,SEPARAÇÃO!$G:$G,"material faltando") -> 0 | E2: {=SUMPRODUCT(--(TEXT(SEPARAÇÃO!D$2:D$9975,"dd/mm/aaaa")=TEXT($A2,"dd/mm/aaaa")),--(SEPARAÇÃO!A$2:A$9975<>""))} -> 30
A3: 46303 | B3: =COUNTIFS(SEPARAÇÃO!$D:$D,A3,SEPARAÇÃO!$H:$H,"BACKLOG") -> 47 | C3: =COUNTIFS(SEPARAÇÃO!$D:$D,A3,SEPARAÇÃO!$H:$H,"saudavel") -> 40 | D3: =COUNTIFS(SEPARAÇÃO!$D:$D,A3,SEPARAÇÃO!$G:$G,"material faltando") -> 0 | E3: {=SUMPRODUCT(--(TEXT(SEPARAÇÃO!D$2:D$9975,"dd/mm/aaaa")=TEXT($A3,"dd/mm/aaaa")),--(SEPARAÇÃO!A$2:A$9975<>""))} -> 84
A4: 46304 | B4: =COUNTIFS(SEPARAÇÃO!$D:$D,A4,SEPARAÇÃO!$H:$H,"BACKLOG") -> 66 | C4: =COUNTIFS(SEPARAÇÃO!$D:$D,A4,SEPARAÇÃO!$H:$H,"saudavel") -> 6 | D4: =COUNTIFS(SEPARAÇÃO!$D:$D,A4,SEPARAÇÃO!$G:$G,"material faltando") -> 0 | E4: {=SUMPRODUCT(--(TEXT(SEPARAÇÃO!D$2:D$9975,"dd/mm/aaaa")=TEXT($A4,"dd/mm/aaaa")),--(SEPARAÇÃO!A$2:A$9975<>""))} -> 67
A5: 46305 | B5: =COUNTIFS(SEPARAÇÃO!$D:$D,A5,SEPARAÇÃO!$H:$H,"BACKLOG") -> 107 | C5: =COUNTIFS(SEPARAÇÃO!$D:$D,A5,SEPARAÇÃO!$H:$H,"saudavel") -> 7 | D5: =COUNTIFS(SEPARAÇÃO!$D:$D,A5,SEPARAÇÃO!$G:$G,"material faltando") -> 6 | E5: {=SUMPRODUCT(--(TEXT(SEPARAÇÃO!D$2:D$9975,"dd/mm/aaaa")=TEXT($A5,"dd/mm/aaaa")),--(SEPARAÇÃO!A$2:A$9975<>""))} -> 107
A6: 46306 | B6: =COUNTIFS(SEPARAÇÃO!$D:$D,A6,SEPARAÇÃO!$H:$H,"BACKLOG") -> 57 | C6: =COUNTIFS(SEPARAÇÃO!$D:$D,A6,SEPARAÇÃO!$H:$H,"saudavel") -> 7 | D6: =COUNTIFS(SEPARAÇÃO!$D:$D,A6,SEPARAÇÃO!$G:$G,"material faltando") -> 2 | E6: {=SUMPRODUCT(--(TEXT(SEPARAÇÃO!D$2:D$9975,"dd/mm/aaaa")=TEXT($A6,"dd/mm/aaaa")),--(SEPARAÇÃO!A$2:A$9975<>""))} -> 62
A7: 46307 | B7: =COUNTIFS(SEPARAÇÃO!$D:$D,A7,SEPARAÇÃO!$H:$H,"BACKLOG") -> 48 | C7: =COUNTIFS(SEPARAÇÃO!$D:$D,A7,SEPARAÇÃO!$H:$H,"saudavel") -> 25 | D7: =COUNTIFS(SEPARAÇÃO!$D:$D,A7,SEPARAÇÃO!$G:$G,"material faltando") -> 3 | E7: {=SUMPRODUCT(--(TEXT(SEPARAÇÃO!D$2:D$9975,"dd/mm/aaaa")=TEXT($A7,"dd/mm/aaaa")),--(SEPARAÇÃO!A$2:A$9975<>""))} -> 67
A8: 46308 | B8: =COUNTIFS(SEPARAÇÃO!$D:$D,A8,SEPARAÇÃO!$H:$H,"BACKLOG") -> 7 | C8: =COUNTIFS(SEPARAÇÃO!$D:$D,A8,SEPARAÇÃO!$H:$H,"saudavel") -> 89 | D8: =COUNTIFS(SEPARAÇÃO!$D:$D,A8,SEPARAÇÃO!$G:$G,"material faltando") -> 0 | E8: {=SUMPRODUCT(--(TEXT(SEPARAÇÃO!D$2:D$9975,"dd/mm/aaaa")=TEXT($A8,"dd/mm/aaaa")),--(SEPARAÇÃO!A$2:A$9975<>""))} -> 90
A9: 46309 | B9: =COUNTIFS(SEPARAÇÃO!$D:$D,A9,SEPARAÇÃO!$H:$H,"BACKLOG") -> 40 | C9: =COUNTIFS(SEPARAÇÃO!$D:$D,A9,SEPARAÇÃO!$H:$H,"saudavel") -> 22 | D9: =COUNTIFS(SEPARAÇÃO!$D:$D,A9,SEPARAÇÃO!$G:$G,"material faltando") -> 0 | E9: {=SUMPRODUCT(--(TEXT(SEPARAÇÃO!D$2:D$9975,"dd/mm/aaaa")=TEXT($A9,"dd/mm/aaaa")),--(SEPARAÇÃO!A$2:A$9975<>""))} -> 60
A10: 46310 | B10: =COUNTIFS(SEPARAÇÃO!$D:$D,A10,SEPARAÇÃO!$H:$H,"BACKLOG") -> 34 | C10: =COUNTIFS(SEPARAÇÃO!$D:$D,A10,SEPARAÇÃO!$H:$H,"saudavel") -> 47 | D10: =COUNTIFS(SEPARAÇÃO!$D:$D,A10,SEPARAÇÃO!$G:$G,"material faltando") -> 1 | E10: {=SUMPRODUCT(--(TEXT(SEPARAÇÃO!D$2:D$9975,"dd/mm/aaaa")=TEXT($A10,"dd/mm/aaaa")),--(SEPARAÇÃO!A$2:A$9975<>""))} -> 51
